Workbook

Sheet Instrukcja
A1: Model: aplikacja carpoolingowa dla studentów w Polsce (stan na 6.10.2026)
A3: Jak używać:
A4: 1. Zmieniaj WYŁĄCZNIE niebieskie liczby (dane wejściowe). Żółte tło = kluczowe założenia, które najmocniej zmieniają wynik.
A5: 2. Czarne liczby to formuły – przeliczają się automatycznie. Zielone = odwołania do innego arkusza.
A6: 3. Kolumna 'Typ' w arkuszu Zalozenia mówi, czy liczba to FAKT (ze źródłem) czy SZACUNEK (moje założenie – zweryfikuj ankietą).
A8: Arkusze:
A9: Zalozenia – wszystkie parametry wejściowe ze źródłami.
A10: Rynek – TAM / SAM / SOM dla Polski i dla korytarza Warszawa–Lublin (wzory widoczne w kolumnie 'Wzór').
A11: Monetyzacja – 7 modeli przychodu przy 1 000 / 10 000 / 50 000 aktywnych użytkowników.
A12: Scenariusze – uproszczony rachunek wyników na 3 lata: pesymistyczny / bazowy / optymistyczny + próg rentowności.
A13: Trasy – porównanie cen i czasów: pociąg (z ulgą 51%), FlixBus, BlaBlaCar, własne auto.
A14: Zrodla – lista źródeł.
... A17: Uwaga: 'aktywny użytkownik' = osoba, która w danym roku odbyła co najmniej 1 przejazd przez aplikację (kierowca lub pasażer).

Sheet Zalozenia
A1: Parametr | B1: Wartość | C1: Jednostka | D1: Typ | E1: Źródło / uzasadnienie
A2: RYNEK – CAŁA POLSKA
A3: Liczba studentów w Polsce, rok akad. 2025/26 | B3: 1322841 | C3: osoby | D3: FAKT | E3: GUS, 'Szkolnictwo wyższe w roku akademickim 2025/2026' (publ. 15.06.2026); za: prawo.pl, portalsamorzadowy.pl, isr.info.pl
A4: Studenci-cudzoziemcy (rok 2024/25 – najnowsze znalezione) | B4: 108600 | C4: osoby | D4: FAKT | E4: GUS, 'Szkolnictwo wyższe i jego finanse w 2024 r.' (za bankier.pl). Wykluczeni z TAM – rzadko jeżdżą co weekend do domu.
A5: Odsetek studentów mieszkających poza domem rodzinnym | B5: 0.5 | C5: % | D5: SZACUNEK | E5: EUROSTUDENT VIII (PBS/MNiSW): ok. połowa polskich studentów mieszka z rodzicami; CBRE (za Eurostudent): 41% w domu rodzinnym, 11% w akademikach, ~połowa wynajmuje.
A6: ...z nich: odsetek jeżdżących do domu regularnie (≥1× w miesiącu) między miastami | B6: 0.6 | C6: % | D6: SZACUNEK | E6: Brak publicznych danych o częstotliwości powrotów do domu – ZWERYFIKUJ ANKIETĄ (kluczowe pytanie MVP).
A7: Przejazdy w jedną stronę na takiego studenta / rok | B7: 24 | C7: przejazdy | D7: SZACUNEK | E7: Założenie: ok. 12 powrotów w obie strony rocznie (mieszanka: co tydzień / co 2–4 tygodnie / tylko święta).
A8: Średnia cena miejsca w carpoolingu (dzielenie kosztów) | B8: 30 | C8: zł | D8: SZACUNEK | E8: Na trasach ~170 km musi konkurować z PKP Intercity z ulgą 51% (ok. 25–27 zł) – patrz arkusz Trasy.
A9: Odsetek regularnie podróżujących otwartych na carpooling | B9: 0.35 | C9: % | D9: SZACUNEK | E9: Brak danych dla studentów. BlaBlaCar deklaruje ~6 mln aktywnych użytkowników w PL (2023, za antyweb.pl) – carpooling jest znany, ale część osób z zasady wybiera pociąg.
A10: Udział ich podróży realizowanych carpoolingiem | B10: 0.4 | C10: % | D10: SZACUNEK | E10: Nawet chętni część podróży robią pociągiem (pogoda, godziny, brak dopasowania).
A11: Odsetek kierowców (auto dostępne w mieście studiów) | B11: 0.2 | C11: % | D11: SZACUNEK | E11: Proxy: CBOS (2018) – 21% uczniów i studentów deklarowało posiadanie samochodu (za wynikami wyszukiwania; raport K_113_18).
A12: Wolne miejsca w aucie na przejazd | B12: 3 | C12: miejsca | D12: SZACUNEK | E12: Typowe auto osobowe: kierowca + 3 pasażerów (wygodnie, z bagażem).
A13: KORYTARZ PILOTAŻOWY: WARSZAWA ↔ LUBLIN
A14: Studenci w Warszawie (2024/25) | B14: 257000 | C14: osoby | D14: FAKT | E14: Knight Frank, 'Prywatne akademiki w Polsce' (na podst. GUS): Warszawa ~257 tys. studentów.
A15: Odsetek studentów w Warszawie pochodzących z woj. lubelskiego | B15: 0.06 | C15: % | D15: SZACUNEK | E15: Brak opublikowanych danych o pochodzeniu studentów warszawskich uczelni – sprawdź w danych uczelni / POL-on.
A16: Studenci uczelni w Lublinie (2022/23 – najnowsze znalezione) | B16: 58196 | C16: osoby | D16: FAKT | E16: Urząd Statystyczny w Lublinie, 'Szkolnictwo wyższe w województwie lubelskim w roku akademickim 2022/2023'.
A17: Odsetek studentów w Lublinie pochodzących z Mazowsza | B17: 0.08 | C17: % | D17: SZACUNEK | E17: Brak danych; Lublin w l. 2011–2020 przyjął >220 tys. nowych studentów z całej Polski (lublin.eu).
A18: Udział osiągalnego rynku korytarza zdobyty w roku 1 | B18: 0.1 | C18: % | D18: SZACUNEK | E18: Realistyczny cel pilotażu na jednej trasie.
A19: MONETYZACJA
A20: Udział pasażerów wśród aktywnych użytkowników | B20: 0.75 | C20: % | D20: SZACUNEK | E20: Kierowców jest zawsze mniej; w BlaBlaCar PL 81,5% kierowców to mężczyźni, wśród pasażerów przeważają kobiety (za wynikami wyszukiwania).
A21: Rezerwacje przez aplikację na pasażera / rok | B21: 8 | C21: rezerwacje | D21: SZACUNEK | E21: Część podróży i tak odbywa się pociągiem.
A22: Prowizja (opłata serwisowa) – % ceny miejsca | B22: 0.12 | C22: % | D22: SZACUNEK | E22: BlaBlaCar PL po powrocie opłat: np. 55 zł → 7 zł, 77 zł → 10 zł (~13%) (antyweb.pl); w 2016: ~20% (3 zł min.). FR: 0–30%, typowo 16–22%.
A23: Operator płatności – prowizja % (karty EOG) | B23: 0.015 | C23: % | D23: FAKT | E23: Stripe Polska: 1,5% + 1 zł dla standardowych kart z EOG (za quasa.io).
A24: Operator płatności – prowizja % (BLIK) | B24: 0.016 | C24: % | D24: FAKT | E24: Stripe Polska: BLIK 1,6% + 1 zł (za quasa.io).
A25: Operator płatności – opłata stała za transakcję | B25: 1 | C25: zł | D25: FAKT | E25: Stripe Polska: +1 zł za transakcję. Przy małych kwotach to zjada większość marży!
A26: Stała opłata za rezerwację (wariant 2) | B26: 2.99 | C26: zł | D26: SZACUNEK | E26: Poziom akceptowalny dla studenta (do zweryfikowania testem).
A27: Subskrypcja pasażera 'Semestr Pass' – cena za semestr | B27: 29 | C27: zł | D27: SZACUNEK | E27: Analog: BlaBlaPass w PL (1 zł za 6 mies. w promocji startowej – bankier.pl / wirtualnemedia.pl).
A28: Konwersja pasażerów na subskrypcję | B28: 0.1 | C28: % | D28: SZACUNEK
A29: Premium dla kierowców – cena miesięczna | B29: 9.99 | C29: zł | D29: SZACUNEK | E29: Np. automatyczne publikowanie stałych tras, wyróżnienie, statystyki.
A30: Konwersja kierowców na premium | B30: 0.05 | C30: % | D30: SZACUNEK
A31: Aktywne miesiące w roku (rok akademicki) | B31: 9 | C31: mies. | D31: SZACUNEK | E31: Październik–czerwiec; lipiec–wrzesień to wakacje (studenci w domu).
A32: Reklamy/partnerstwa marek: przychód na aktywnego użytkownika / rok | B32: 5 | C32: zł | D32: SZACUNEK | E32: Banki, telekomy, gastronomia dla studentów. Bardzo niepewne.
A33: Minimalna skala, od której da się sprzedawać reklamy/partnerstwa | B33: 5000 | C33: użytk. | D33: SZACUNEK | E33: Poniżej tej skali reklamodawcy zwykle nie rozmawiają.
A34: Roczna licencja dla jednej uczelni (white-label / program dojazdów) | B34: 15000 | C34: zł | D34: SZACUNEK | E34: Model Zimride (licencje dla uczelni i firm). Uczelnie publiczne – zamówienia publiczne, długie decyzje.
A35: Aktywni użytkownicy przypadający na 1 płacącą uczelnię | B35: 5000 | C35: użytk. | D35: SZACUNEK | E35: Uczelnia zapłaci dopiero, gdy aplikacja ma realną skalę na jej kampusie.
A36: Afiliacja (bilety PKP/FlixBus gdy brak przejazdu, ubezpieczenia): przychód / użytkownik / rok | B36: 2 | C36: zł | D36: SZACUNEK | E36: Pośrednictwo w ubezpieczeniach wymaga zgodności z przepisami o dystrybucji ubezpieczeń.
A37: KOSZTY
A38: Kurs USD/PLN | B38: 3.7 | C38: zł | D38: SZACUNEK | E38: Zaktualizuj do bieżącego kursu NBP.
A39: Koszt instalacji (CPI) – Android, Europa | B39: 1.41 | C39: USD | D39: FAKT | E39: mapendo.co, 'Cost per Install 2025' (Europa: Android 1,41 USD, iOS 2,31 USD).
A40: Koszt instalacji (CPI) – iOS, Europa | B40: 2.31 | C40: USD | D40: FAKT | E40: jw.
...

Sheet Rynek
A1: Pozycja | B1: Wartość | C1: Jednostka | D1: Wzór (opis)
A2: TAM – całkowity rynek (Polska)
A3: Studenci krajowi | B3: =Zalozenia!$B$3-Zalozenia!$B$4 -> 1214241 | C3: osoby | D3: studenci ogółem − cudzoziemcy
A4: Mieszkający poza domem rodzinnym | B4: =B3*Zalozenia!$B$5 -> 607120.5 | C4: osoby | D4: studenci krajowi × % poza domem
A5: TAM: regularnie jeżdżący do domu między miastami | B5: =B4*Zalozenia!$B$6 -> 364272.3 | C5: osoby | D5: × % regularnie podróżujących
A6: TAM: przejazdy w jedną stronę / rok | B6: =B5*Zalozenia!$B$7 -> 8742535.2 | C6: przejazdy | D6: TAM osoby × przejazdy na osobę
A7: TAM: wartość tych przejazdów przy cenie carpoolingu (GMV) | B7: =B6*Zalozenia!$B$8 -> 262276056 | C7: zł / rok | D7: przejazdy × średnia cena miejsca – teoretyczne maksimum
A8: Kontrola: przejazdy studentów i doktorantów w PKP Intercity w 2025 r. | B8: 13700000 | C8: przejazdy | D8: FAKT: PKP Intercity, podsumowanie 2025 (13,7 mln, +17% r/r) – rząd wielkości zgodny z TAM
A9: SAM – rynek osiągalny (Polska)
A10: SAM: osoby otwarte na carpooling | B10: =B5*Zalozenia!$B$9 -> 127495.3 | C10: osoby | D10: TAM osoby × % otwartych na carpooling
A11: SAM: przejazdy carpoolingiem / rok | B11: =B10*Zalozenia!$B$7*Zalozenia!$B$10 -> 1223954.9 | C11: przejazdy | D11: × przejazdy na osobę × udział carpoolingu
A12: SAM: GMV / rok | B12: =B11*Zalozenia!$B$8 -> 36718648 | C12: zł / rok | D12: przejazdy × cena
A13: SAM: przychód platformy przy 100% udziału (prowizja brutto) | B13: =B11*Zalozenia!$B$56 -> 4406237.7 | C13: zł / rok | D13: przejazdy × prowizja brutto – SUFIT przychodów z prowizji w całej Polsce
A14: SAM: przychód netto po kosztach płatności przy 100% udziału | B14: =B11*Zalozenia!$B$55 -> 2565409.5 | C14: zł / rok | D14: przejazdy × prowizja netto
A15: Kontrola podaży: kierowcy w SAM | B15: =B10*Zalozenia!$B$11 -> 25499.061 | C15: osoby | D15: SAM × % kierowców
A16: Kontrola podaży: oferowane miejsca / rok | B16: =B15*Zalozenia!$B$7*Zalozenia!$B$10*Zalozenia!$B$12 -> 734372.96 | C16: miejsca | D16: kierowcy × przejazdy × udział carpoolingu × wolne miejsca
A17: Kontrola popytu: potrzebne miejsca (pasażerowie w SAM) | B17: =(B10-B15)*Zalozenia!$B$7*Zalozenia!$B$10 -> 979163.94 | C17: miejsca | D17: (SAM − kierowcy) × przejazdy × udział carpoolingu
A18: Wskaźnik pokrycia popytu podażą (krajowo) | B18: =IF(B17=0,0,B16/B17) -> 0.75 | C18: x | D18: >1 = w skali kraju miejsc jest dość; problemem jest dopasowanie trasa+godzina
A19: SOM – korytarz Warszawa ↔ Lublin (pilotaż)
A20: Studenci w Warszawie z woj. lubelskiego | B20: =Zalozenia!$B$14*Zalozenia!$B$15 -> 15420 | C20: osoby | D20: studenci W-wy × % z lubelskiego
A21: Studenci w Lublinie z Mazowsza | B21: =Zalozenia!$B$16*Zalozenia!$B$17 -> 4655.68 | C21: osoby | D21: studenci Lublina × % z Mazowsza
A22: Studenci powiązani z korytarzem | B22: =B20+B21 -> 20075.68 | C22: osoby | D22: suma
A23: ...regularnie podróżujący | B23: =B22*Zalozenia!$B$6 -> 12045.408 | C23: osoby | D23: × % regularnie podróżujących
A24: ...otwarci na carpooling (rynek osiągalny korytarza) | B24: =B23*Zalozenia!$B$9 -> 4215.8928 | C24: osoby | D24: × % otwartych
A25: SOM rok 1 (korytarz) | B25: =B24*Zalozenia!$B$18 -> 421.58928 | C25: aktywni użytk. | D25: × udział zdobyty w roku 1
A26: Przejazdy carpoolingiem w korytarzu / rok przy pełnym rynku osiągalnym | B26: =B24*Zalozenia!$B$7*Zalozenia!$B$10 -> 40472.571 | C26: przejazdy
A27: Średnio przejazdów na jeden weekend (35 weekendów akademickich) | B27: =B26/35 -> 1156.3592 | C27: przejazdy | D27: rozkład na ok. 35 weekendów roku akademickiego
A29: SOM dla całej aplikacji w latach 1–3 – patrz arkusz Scenariusze (wiersz 'Aktywni użytkownicy').

Sheet Monetyzacja
A1: Model | B1: Opis | C1: Założona opłata | D1: Przychód netto na aktywnego użytk./rok | E1: 1 000 aktywnych | F1: 10 000 aktywnych | G1: 50 000 aktywnych | H1: Zalety | I1: Wady
A2: Skala (aktywni użytkownicy) → | E2: 1000 | F2: 10000 | G2: 50000
A3: 1. Prowizja od przejazdu (opłata serwisowa pasażera) | B3: Pasażer płaci w aplikacji cenę miejsca + % opłaty; kierowca dostaje zwrot kosztów. Płatność z góry ogranicza 'no-show'. | C3: 12% ceny miejsca (ok. 3,6 zł przy 30 zł) | D3: =Zalozenia!$B$20*Zalozenia!$B$21*Zalozenia!$B$55 -> 12.576 | E3: =$D3*E$2 -> 12576 | F3: =$D3*F$2 -> 125760 | G3: =$D3*G$2 -> 628800 | H3: Skaluje się z wolumenem; standard rynku (BlaBlaCar); płatność z góry zmniejsza odwołania. | I3: Przy niskich cenach studenckich stała opłata operatora (1 zł) zjada ~1/3 marży; studenci uciekają do darmowych grup FB; BlaBlaCar w PL musiał się z opłat wycofać w 2017.
A4: 2. Stała opłata za rezerwację | B4: Pasażer płaci tylko 2,99 zł online; pieniądze za paliwo – BLIK/gotówka bezpośrednio kierowcy. | C4: 2,99 zł / rezerwacja | D4: =Zalozenia!$B$20*Zalozenia!$B$21*(Zalozenia!$B$26-(Zalozenia!$B$26*Zalozenia!$B$24+Zalozenia!$B$25)) -> 11.65296 | E4: =$D4*E$2 -> 11652.96 | F4: =$D4*F$2 -> 116529.6 | G4: =$D4*G$2 -> 582648 | H4: Prosta komunikacja; platforma nie przechowuje pieniędzy kierowców (mniej problemów regulacyjnych z usługami płatniczymi). | I4: Niski przychód; użytkownicy mogą umawiać się poza aplikacją po pierwszym kontakcie (disintermediation).
A5: 3. Subskrypcja pasażera 'Semestr Pass' | B5: Brak opłat za rezerwacje w zamian za opłatę semestralną. | C5: 29 zł / semestr, 10% pasażerów | D5: =Zalozenia!$B$20*Zalozenia!$B$28*2*(Zalozenia!$B$27-(Zalozenia!$B$27*Zalozenia!$B$24+Zalozenia!$B$25)) -> 4.1304 | E5: =$D5*E$2 -> 4130.4 | F5: =$D5*F$2 -> 41304 | G5: =$D5*G$2 -> 206520 | H5: Przewidywalny przychód; pasuje do rytmu semestrów; jedna płatność = niski koszt transakcyjny. | I5: Niska konwersja; sezonowość (lato bez przychodu); BlaBlaPass w PL był tylko etapem przejściowym.
A6: 4. Premium dla kierowców | B6: Stałe trasy publikowane automatycznie, wyróżnienie ogłoszeń, statystyki zwrotów kosztów. | C6: 9,99 zł / mies., 5% kierowców, 9 mies. | D6: =(1-Zalozenia!$B$20)*Zalozenia!$B$30*Zalozenia!$B$31*(Zalozenia!$B$29-(Zalozenia!$B$29*Zalozenia!$B$23+Zalozenia!$B$25)) -> 0.99451687 | E6: =$D6*E$2 -> 994.51688 | F6: =$D6*F$2 -> 9945.1688 | G6: =$D6*G$2 -> 49725.844 | H6: Nie obciąża pasażerów (strona wrażliwa na cenę). | I6: Kierowcy to strona deficytowa – nie wolno ich zniechęcać; bardzo mały przychód.
A7: 5. Reklamy i partnerstwa marek | B7: Banki (konta studenckie), telekomy, gastronomia, festiwale – sponsoring tras, kody rabatowe. | C7: ok. 5 zł / aktywnego użytk. / rok od 5 000 użytk. | D7: zależy od skali | E7: =IF(E$2>=Zalozenia!$B$33,E$2*Zalozenia!$B$32,0) -> 0 | F7: =IF(F$2>=Zalozenia!$B$33,F$2*Zalozenia!$B$32,0) -> 50000 | G7: =IF(G$2>=Zalozenia!$B$33,G$2*Zalozenia!$B$32,0) -> 250000 | H7: Nie obciąża użytkowników; marki chcą docierać do studentów. | I7: Wymaga skali; reklamy pogarszają UX; przychody nieregularne.
A8: 6. Licencje dla uczelni (B2B2C) | B8: White-label / program wspólnych dojazdów dla studentów i pracowników (redukcja parkingów, cele klimatyczne). | C8: 15 000 zł / uczelnię / rok; 1 uczelnia na 5 000 użytk. | D8: zależy od skali | E8: =ROUNDDOWN(E$2/Zalozenia!$B$35,0)*Zalozenia!$B$34 -> 0 | F8: =ROUNDDOWN(F$2/Zalozenia!$B$35,0)*Zalozenia!$B$34 -> 30000 | G8: =ROUNDDOWN(G$2/Zalozenia!$B$35,0)*Zalozenia!$B$34 -> 150000 | H8: Zaufanie (weryfikacja przez uczelnię), kanał dystrybucji; precedens: Politechnika Wrocławska + otodojazd.pl; Zimride w USA. | I8: Długie decyzje i zamówienia publiczne; małe budżety; Zimride zarabiał na tym za mało i został sprzedany.
A9: 7. Afiliacja i oferty dla firm | B9: Bilety PKP/FlixBus, gdy brak przejazdu; ubezpieczenia NNW dla kierowców; rabaty na paliwo. | C9: ok. 2 zł / aktywnego użytk. / rok | D9: =Zalozenia!$B$36 -> 2 | E9: =$D9*E$2 -> 2000 | F9: =$D9*F$2 -> 20000 | G9: =$D9*G$2 -> 100000 | H9: Monetyzuje też nieudane wyszukiwania (zrobił to BlaBlaCar, sprzedając bilety autobusowe i kolejowe). | I9: Niskie stawki; dystrybucja ubezpieczeń wymaga zgodności z przepisami (IDD).
A10: Rekomendowany miks na start (2 + 7): opłata stała + afiliacja | E10: =E4+E9 -> 13652.96 | F10: =F4+F9 -> 136529.6 | G10: =G4+G9 -> 682648
A11: Miks docelowy (1 + 5 + 6 + 7): prowizja + partnerstwa + uczelnie + afiliacja | E11: =E3+E7+E8+E9 -> 14576 | F11: =F3+F7+F8+F9 -> 225760 | G11: =G3+G7+G8+G9 -> 1128800
A13: Uwaga: modele 1, 2 i 3 to warianty tego samego strumienia (opłata pasażera) – nie sumuj ich ze sobą. Kwoty netto po kosztach operatora płatności, przed kosztami firmy.

Sheet Scenariusze
A1: Uproszczony rachunek wyników na 3 lata (zł). Niebieskie = założenia scenariusza (edytuj).
A2: Pozycja | B2: Pes. R1 | C2: Pes. R2 | D2: Pes. R3 | E2: Baz. R1 | F2: Baz. R2 | G2: Baz. R3 | H2: Opt. R1 | I2: Opt. R2 | J2: Opt. R3
A3: Aktywni użytkownicy (SOM) | B3: 300 | C3: 1000 | D3: 2500 | E3: 800 | F3: 4000 | G3: 12000 | H3: 2000 | I3: 10000 | J3: 30000
A4: Pobieramy opłatę od pasażerów? (1=tak, 0=nie – darmowy start) | B4: 0 | C4: 1 | D4: 1 | E4: 0 | F4: 1 | G4: 1 | H4: 0 | I4: 1 | J4: 1
A5: Rozwój aplikacji (no-code/freelancer/software house) | B5: 10000 | C5: 20000 | D5: 30000 | E5: 30000 | F5: 60000 | G5: 100000 | H5: 150000 | I5: 150000 | J5: 200000
A6: Program ambasadorów i eventy | B6: 2000 | C6: 5000 | D6: 8000 | E6: 5000 | F6: 15000 | G6: 30000 | H6: 10000 | I6: 30000 | J6: 60000
A7: Prawnik (regulamin, RODO, opinia transport/podatki) | B7: 8000 | C7: 3000 | D7: 3000 | E7: 12000 | F7: 5000 | G7: 8000 | H7: 15000 | I7: 8000 | J7: 10000
A8: Wynagrodzenia zespołu (koszt pracodawcy) | B8: 0 | C8: 0 | D8: 0 | E8: 0 | F8: 120000 | G8: 240000 | H8: 60000 | I8: 360000 | J8: 600000
A10: WOLUMEN
A11: Nowi aktywni użytkownicy | B11: =B3 -> 300 | C11: =MAX(0,C3-B3*(1-Zalozenia!$B$44)) -> 820 | D11: =MAX(0,D3-C3*(1-Zalozenia!$B$44)) -> 1900 | E11: =E3 -> 800 | F11: =MAX(0,F3-E3*(1-Zalozenia!$B$44)) -> 3520 | G11: =MAX(0,G3-F3*(1-Zalozenia!$B$44)) -> 9600 | H11: =H3 -> 2000 | I11: =MAX(0,I3-H3*(1-Zalozenia!$B$44)) -> 8800 | J11: =MAX(0,J3-I3*(1-Zalozenia!$B$44)) -> 24000
A12: Rezerwacje pasażerów | B12: =B3*Zalozenia!$B$20*Zalozenia!$B$21 -> 1800 | C12: =C3*Zalozenia!$B$20*Zalozenia!$B$21 -> 6000 | D12: =D3*Zalozenia!$B$20*Zalozenia!$B$21 -> 15000 | E12: =E3*Zalozenia!$B$20*Zalozenia!$B$21 -> 4800 | F12: =F3*Zalozenia!$B$20*Zalozenia!$B$21 -> 24000 | G12: =G3*Zalozenia!$B$20*Zalozenia!$B$21 -> 72000 | H12: =H3*Zalozenia!$B$20*Zalozenia!$B$21 -> 12000 | I12: =I3*Zalozenia!$B$20*Zalozenia!$B$21 -> 60000 | J12: =J3*Zalozenia!$B$20*Zalozenia!$B$21 -> 180000
A13: Wartość przejazdów (GMV) | B13: =B12*Zalozenia!$B$8 -> 54000 | C13: =C12*Zalozenia!$B$8 -> 180000 | D13: =D12*Zalozenia!$B$8 -> 450000 | E13: =E12*Zalozenia!$B$8 -> 144000 | F13: =F12*Zalozenia!$B$8 -> 720000 | G13: =G12*Zalozenia!$B$8 -> 2160000 | H13: =H12*Zalozenia!$B$8 -> 360000 | I13: =I12*Zalozenia!$B$8 -> 1800000 | J13: =J12*Zalozenia!$B$8 -> 5400000
A14: PRZYCHODY (netto po kosztach płatności)
A15: Prowizja od przejazdów | B15: =B4*B12*Zalozenia!$B$55 -> 0 | C15: =C4*C12*Zalozenia!$B$55 -> 12576 | D15: =D4*D12*Zalozenia!$B$55 -> 31440 | E15: =E4*E12*Zalozenia!$B$55 -> 0 | F15: =F4*F12*Zalozenia!$B$55 -> 50304 | G15: =G4*G12*Zalozenia!$B$55 -> 150912 | H15: =H4*H12*Zalozenia!$B$55 -> 0 | I15: =I4*I12*Zalozenia!$B$55 -> 125760 | J15: =J4*J12*Zalozenia!$B$55 -> 377280
A16: Reklamy i partnerstwa | B16: =IF(B3>=Zalozenia!$B$33,B3*Zalozenia!$B$32,0) -> 0 | C16: =IF(C3>=Zalozenia!$B$33,C3*Zalozenia!$B$32,0) -> 0 | D16: =IF(D3>=Zalozenia!$B$33,D3*Zalozenia!$B$32,0) -> 0 | E16: =IF(E3>=Zalozenia!$B$33,E3*Zalozenia!$B$32,0) -> 0 | F16: =IF(F3>=Zalozenia!$B$33,F3*Zalozenia!$B$32,0) -> 0 | G16: =IF(G3>=Zalozenia!$B$33,G3*Zalozenia!$B$32,0) -> 60000 | H16: =IF(H3>=Zalozenia!$B$33,H3*Zalozenia!$B$32,0) -> 0 | I16: =IF(I3>=Zalozenia!$B$33,I3*Zalozenia!$B$32,0) -> 50000 | J16: =IF(J3>=Zalozenia!$B$33,J3*Zalozenia!$B$32,0) -> 150000
A17: Licencje dla uczelni | B17: =ROUNDDOWN(B3/Zalozenia!$B$35,0)*Zalozenia!$B$34 -> 0 | C17: =ROUNDDOWN(C3/Zalozenia!$B$35,0)*Zalozenia!$B$34 -> 0 | D17: =ROUNDDOWN(D3/Zalozenia!$B$35,0)*Zalozenia!$B$34 -> 0 | E17: =ROUNDDOWN(E3/Zalozenia!$B$35,0)*Zalozenia!$B$34 -> 0 | F17: =ROUNDDOWN(F3/Zalozenia!$B$35,0)*Zalozenia!$B$34 -> 0 | G17: =ROUNDDOWN(G3/Zalozenia!$B$35,0)*Zalozenia!$B$34 -> 30000 | H17: =ROUNDDOWN(H3/Zalozenia!$B$35,0)*Zalozenia!$B$34 -> 0 | I17: =ROUNDDOWN(I3/Zalozenia!$B$35,0)*Zalozenia!$B$34 -> 30000 | J17: =ROUNDDOWN(J3/Zalozenia!$B$35,0)*Zalozenia!$B$34 -> 90000
A18: Afiliacja | B18: =B3*Zalozenia!$B$36 -> 600 | C18: =C3*Zalozenia!$B$36 -> 2000 | D18: =D3*Zalozenia!$B$36 -> 5000 | E18: =E3*Zalozenia!$B$36 -> 1600 | F18: =F3*Zalozenia!$B$36 -> 8000 | G18: =G3*Zalozenia!$B$36 -> 24000 | H18: =H3*Zalozenia!$B$36 -> 4000 | I18: =I3*Zalozenia!$B$36 -> 20000 | J18: =J3*Zalozenia!$B$36 -> 60000
A19: PRZYCHODY RAZEM | B19: =SUM(B15:B18) -> 600 | C19: =SUM(C15:C18) -> 14576 | D19: =SUM(D15:D18) -> 36440 | E19: =SUM(E15:E18) -> 1600 | F19: =SUM(F15:F18) -> 58304 | G19: =SUM(G15:G18) -> 264912 | H19: =SUM(H15:H18) -> 4000 | I19: =SUM(I15:I18) -> 225760 | J19: =SUM(J15:J18) -> 677280
A20: KOSZTY
A21: Rozwój aplikacji | B21: =B5 -> 10000 | C21: =C5 -> 20000 | D21: =D5 -> 30000 | E21: =E5 -> 30000 | F21: =F5 -> 60000 | G21: =G5 -> 100000 | H21: =H5 -> 150000 | I21: =I5 -> 150000 | J21: =J5 -> 200000
A22: Marketing płatny (nowi × (1 − organiczni) × CAC) | B22: =B11*(1-Zalozenia!$B$43)*Zalozenia!$B$54 -> 3929.4 | C22: =C11*(1-Zalozenia!$B$43)*Zalozenia!$B$54 -> 10740.36 | D22: =D11*(1-Zalozenia!$B$43)*Zalozenia!$B$54 -> 24886.2 | E22: =E11*(1-Zalozenia!$B$43)*Zalozenia!$B$54 -> 10478.4 | F22: =F11*(1-Zalozenia!$B$43)*Zalozenia!$B$54 -> 46104.96 | G22: =G11*(1-Zalozenia!$B$43)*Zalozenia!$B$54 -> 125740.8 | H22: =H11*(1-Zalozenia!$B$43)*Zalozenia!$B$54 -> 26196 | I22: =I11*(1-Zalozenia!$B$43)*Zalozenia!$B$54 -> 115262.4 | J22: =J11*(1-Zalozenia!$B$43)*Zalozenia!$B$54 -> 314352
A23: Ambasadorzy i eventy | B23: =B6 -> 2000 | C23: =C6 -> 5000 | D23: =D6 -> 8000 | E23: =E6 -> 5000 | F23: =F6 -> 15000 | G23: =G6 -> 30000 | H23: =H6 -> 10000 | I23: =I6 -> 30000 | J23: =J6 -> 60000
A24: Prawnik | B24: =B7 -> 8000 | C24: =C7 -> 3000 | D24: =D7 -> 3000 | E24: =E7 -> 12000 | F24: =F7 -> 5000 | G24: =G7 -> 8000 | H24: =H7 -> 15000 | I24: =I7 -> 8000 | J24: =J7 -> 10000
A25: Księgowość | B25: =Zalozenia!$B$49 -> 6000 | C25: =Zalozenia!$B$49 -> 6000 | D25: =Zalozenia!$B$49 -> 6000 | E25: =Zalozenia!$B$49 -> 6000 | F25: =Zalozenia!$B$49 -> 6000 | G25: =Zalozenia!$B$49 -> 6000 | H25: =Zalozenia!$B$49 -> 6000 | I25: =Zalozenia!$B$49 -> 6000 | J25: =Zalozenia!$B$49 -> 6000
A26: Serwery, mapy, SMS, konta deweloperskie | B26: =Zalozenia!$B$45+Zalozenia!$B$48+B3*Zalozenia!$B$46 -> 4400 | C26: =Zalozenia!$B$45+Zalozenia!$B$48+C3*Zalozenia!$B$46 -> 5100 | D26: =Zalozenia!$B$45+Zalozenia!$B$48+D3*Zalozenia!$B$46 -> 6600 | E26: =Zalozenia!$B$45+Zalozenia!$B$48+E3*Zalozenia!$B$46 -> 4900 | F26: =Zalozenia!$B$45+Zalozenia!$B$48+F3*Zalozenia!$B$46 -> 8100 | G26: =Zalozenia!$B$45+Zalozenia!$B$48+G3*Zalozenia!$B$46 -> 16100 | H26: =Zalozenia!$B$45+Zalozenia!$B$48+H3*Zalozenia!$B$46 -> 6100 | I26: =Zalozenia!$B$45+Zalozenia!$B$48+I3*Zalozenia!$B$46 -> 14100 | J26: =Zalozenia!$B$45+Zalozenia!$B$48+J3*Zalozenia!$B$46 -> 34100
A27: Ubezpieczenie | B27: =Zalozenia!$B$50 -> 3000 | C27: =Zalozenia!$B$50 -> 3000 | D27: =Zalozenia!$B$50 -> 3000 | E27: =Zalozenia!$B$50 -> 3000 | F27: =Zalozenia!$B$50 -> 3000 | G27: =Zalozenia!$B$50 -> 3000 | H27: =Zalozenia!$B$50 -> 3000 | I27: =Zalozenia!$B$50 -> 3000 | J27: =Zalozenia!$B$50 -> 3000
A28: Obsługa klienta i moderacja | B28: =B3*Zalozenia!$B$47 -> 900 | C28: =C3*Zalozenia!$B$47 -> 3000 | D28: =D3*Zalozenia!$B$47 -> 7500 | E28: =E3*Zalozenia!$B$47 -> 2400 | F28: =F3*Zalozenia!$B$47 -> 12000 | G28: =G3*Zalozenia!$B$47 -> 36000 | H28: =H3*Zalozenia!$B$47 -> 6000 | I28: =I3*Zalozenia!$B$47 -> 30000 | J28: =J3*Zalozenia!$B$47 -> 90000
A29: Wynagrodzenia | B29: =B8 -> 0 | C29: =C8 -> 0 | D29: =D8 -> 0 | E29: =E8 -> 0 | F29: =F8 -> 120000 | G29: =G8 -> 240000 | H29: =H8 -> 60000 | I29: =I8 -> 360000 | J29: =J8 -> 600000
A30: KOSZTY RAZEM | B30: =SUM(B21:B29) -> 38229.4 | C30: =SUM(C21:C29) -> 55840.36 | D30: =SUM(D21:D29) -> 88986.2 | E30: =SUM(E21:E29) -> 73778.4 | F30: =SUM(F21:F29) -> 275204.96 | G30: =SUM(G21:G29) -> 564840.8 | H30: =SUM(H21:H29) -> 282296 | I30: =SUM(I21:I29) -> 716362.4 | J30: =SUM(J21:J29) -> 1317452
A31: WYNIK
A32: Wynik roczny (przychody − koszty) | B32: =B19-B30 -> -37629.4 | C32: =C19-C30 -> -41264.36 | D32: =D19-D30 -> -52546.2 | E32: =E19-E30 -> -72178.4 | F32: =F19-F30 -> -216900.96 | G32: =G19-G30 -> -299928.8 | H32: =H19-H30 -> -278296 | I32: =I19-I30 -> -490602.4 | J32: =J19-J30 -> -640172
A33: Wynik skumulowany (potrzebne finansowanie, jeśli ujemny) | B33: =B32 -> -37629.4 | C33: =B33+C32 -> -78893.76 | D33: =C33+D32 -> -131439.96 | E33: =E32 -> -72178.4 | F33: =E33+F32 -> -289079.36 | G33: =F33+G32 -> -589008.16 | H33: =H32 -> -278296 | I33: =H33+I32 -> -768898.4 | J33: =I33+J32 -> -1409070.4
A34: Przychód / koszty | B34: =IF(B30=0,0,B19/B30) -> 0.015694727 | C34: =IF(C30=0,0,C19/C30) -> 0.26102984 | D34: =IF(D30=0,0,D19/D30) -> 0.4095017 | E34: =IF(E30=0,0,E19/E30) -> 0.021686564 | F34: =IF(F30=0,0,F19/F30) -> 0.21185665 | G34: =IF(G30=0,0,G19/G30) -> 0.46900295 | H34: =IF(H30=0,0,H19/H30) -> 0.014169524 | I34: =IF(I30=0,0,I19/I30) -> 0.31514775 | J34: =IF(J30=0,0,J19/J30) -> 0.51408325
A35: PRÓG RENTOWNOŚCI (przy kosztach stałych danego roku)
A36: Koszty stałe (rozwój, ambasadorzy, prawnik, księgowość, serwery, ubezpieczenie, wynagrodzenia) | B36: =B21+B23+B24+B25+Zalozenia!$B$45+Zalozenia!$B$48+B27+B29 -> 33100 | C36: =C21+C23+C24+C25+Zalozenia!$B$45+Zalozenia!$B$48+C27+C29 -> 41100 | D36: =D21+D23+D24+D25+Zalozenia!$B$45+Zalozenia!$B$48+D27+D29 -> 54100 | E36: =E21+E23+E24+E25+Zalozenia!$B$45+Zalozenia!$B$48+E27+E29 -> 60100 | F36: =F21+F23+F24+F25+Zalozenia!$B$45+Zalozenia!$B$48+F27+F29 -> 213100 | G36: =G21+G23+G24+G25+Zalozenia!$B$45+Zalozenia!$B$48+G27+G29 -> 391100 | H36: =H21+H23+H24+H25+Zalozenia!$B$45+Zalozenia!$B$48+H27+H29 -> 248100 | I36: =I21+I23+I24+I25+Zalozenia!$B$45+Zalozenia!$B$48+I27+I29 -> 561100 | J36: =J21+J23+J24+J25+Zalozenia!$B$45+Zalozenia!$B$48+J27+J29 -> 883100
A37: Przychód na aktywnego użytkownika przy pełnej monetyzacji (prowizja + reklamy + uczelnie + afiliacja) | B37: =Zalozenia!$B$20*Zalozenia!$B$21*Zalozenia!$B$55+Zalozenia!$B$32+Zalozenia!$B$34/Zalozenia!$B$35+Zalozenia!$B$36 -> 22.576 | C37: =Zalozenia!$B$20*Zalozenia!$B$21*Zalozenia!$B$55+Zalozenia!$B$32+Zalozenia!$B$34/Zalozenia!$B$35+Zalozenia!$B$36 -> 22.576 | D37: =Zalozenia!$B$20*Zalozenia!$B$21*Zalozenia!$B$55+Zalozenia!$B$32+Zalozenia!$B$34/Zalozenia!$B$35+Zalozenia!$B$36 -> 22.576 | E37: =Zalozenia!$B$20*Zalozenia!$B$21*Zalozenia!$B$55+Zalozenia!$B$32+Zalozenia!$B$34/Zalozenia!$B$35+Zalozenia!$B$36 -> 22.576 | F37: =Zalozenia!$B$20*Zalozenia!$B$21*Zalozenia!$B$55+Zalozenia!$B$32+Zalozenia!$B$34/Zalozenia!$B$35+Zalozenia!$B$36 -> 22.576 | G37: =Zalozenia!$B$20*Zalozenia!$B$21*Zalozenia!$B$55+Zalozenia!$B$32+Zalozenia!$B$34/Zalozenia!$B$35+Zalozenia!$B$36 -> 22.576 | H37: =Zalozenia!$B$20*Zalozenia!$B$21*Zalozenia!$B$55+Zalozenia!$B$32+Zalozenia!$B$34/Zalozenia!$B$35+Zalozenia!$B$36 -> 22.576 | I37: =Zalozenia!$B$20*Zalozenia!$B$21*Zalozenia!$B$55+Zalozenia!$B$32+Zalozenia!$B$34/Zalozenia!$B$35+Zalozenia!$B$36 -> 22.576 | J37: =Zalozenia!$B$20*Zalozenia!$B$21*Zalozenia!$B$55+Zalozenia!$B$32+Zalozenia!$B$34/Zalozenia!$B$35+Zalozenia!$B$36 -> 22.576
A38: Koszt zmienny na użytkownika (infrastruktura + obsługa + odtworzenie churnu przez marketing) | B38: =Zalozenia!$B$46+Zalozenia!$B$47+Zalozenia!$B$44*(1-Zalozenia!$B$43)*Zalozenia!$B$54 -> 9.2392 | C38: =Zalozenia!$B$46+Zalozenia!$B$47+Zalozenia!$B$44*(1-Zalozenia!$B$43)*Zalozenia!$B$54 -> 9.2392 | D38: =Zalozenia!$B$46+Zalozenia!$B$47+Zalozenia!$B$44*(1-Zalozenia!$B$43)*Zalozenia!$B$54 -> 9.2392 | E38: =Zalozenia!$B$46+Zalozenia!$B$47+Zalozenia!$B$44*(1-Zalozenia!$B$43)*Zalozenia!$B$54 -> 9.2392 | F38: =Zalozenia!$B$46+Zalozenia!$B$47+Zalozenia!$B$44*(1-Zalozenia!$B$43)*Zalozenia!$B$54 -> 9.2392 | G38: =Zalozenia!$B$46+Zalozenia!$B$47+Zalozenia!$B$44*(1-Zalozenia!$B$43)*Zalozenia!$B$54 -> 9.2392 | H38: =Zalozenia!$B$46+Zalozenia!$B$47+Zalozenia!$B$44*(1-Zalozenia!$B$43)*Zalozenia!$B$54 -> 9.2392 | I38: =Zalozenia!$B$46+Zalozenia!$B$47+Zalozenia!$B$44*(1-Zalozenia!$B$43)*Zalozenia!$B$54 -> 9.2392 | J38: =Zalozenia!$B$46+Zalozenia!$B$47+Zalozenia!$B$44*(1-Zalozenia!$B$43)*Zalozenia!$B$54 -> 9.2392
A39: Próg rentowności: potrzebni aktywni użytkownicy | B39: =IF(B37-B38<=0,0,B36/(B37-B38)) -> 2481.8547 | C39: =IF(C37-C38<=0,0,C36/(C37-C38)) -> 3081.6988 | D39: =IF(D37-D38<=0,0,D36/(D37-D38)) -> 4056.4453 | E39: =IF(E37-E38<=0,0,E36/(E37-E38)) -> 4506.3284 | F39: =IF(F37-F38<=0,0,F36/(F37-F38)) -> 15978.346 | G39: =IF(G37-G38<=0,0,G36/(G37-G38)) -> 29324.876 | H39: =IF(H37-H38<=0,0,H36/(H37-H38)) -> 18602.663 | I39: =IF(I37-I38<=0,0,I36/(I37-I38)) -> 42071.561 | J39: =IF(J37-J38<=0,0,J36/(J37-J38)) -> 66215.284
A40: Próg rentowności jako % krajowego SAM | B40: =B39/Rynek!$B$10 -> 0.019466244 | C40: =C39/Rynek!$B$10 -> 0.024171076 | D40: =D39/Rynek!$B$10 -> 0.031816429 | E40: =E39/Rynek!$B$10 -> 0.035345053 | F40: =F39/Rynek!$B$10 -> 0.12532497 | G40: =G39/Rynek!$B$10 -> 0.23000749 | H40: =H39/Rynek!$B$10 -> 0.14590861 | I40: =I39/Rynek!$B$10 -> 0.32998518 | J40: =J39/Rynek!$B$10 -> 0.51935469
A42: Interpretacja: jeśli próg rentowności przekracza kilkanaście–kilkadziesiąt % krajowego SAM, biznes jest rentowny tylko przy dominacji rynku, której BlaBlaCar (ok. 6 mln aktywnych użytkowników w PL) nie odda bez walki.

Sheet Trasy
A1: Porównanie tras studenckich (ceny z różnych dat 2025–2026; sprawdź aktualne w KOLEO/FlixBus/BlaBlaCar)
A2: Spalanie auta (l/100 km) | B2: 6.5 | C2: SZACUNEK – typowe auto kompaktowe na trasie
A3: Cena Pb95 (zł/l) | B3: 6.79 | C3: FAKT: cena maksymalna Pb95 w rządowym programie CPN na 6.10.2026 (tvp.info, interia.pl)
A4: Ulga studencka (ustawowa, do 26 lat) | B4: 0.51 | C4: FAKT: 51% w PKP Intercity (2 kl.) i pociągach regionalnych (intercity.pl)
A6: Trasa | B6: Dystans drogowy (km, ok.) | C6: Pociąg: najszybszy czas | D6: Pociąg: bilet normalny 2 kl. od (zł) | E6: Pociąg: bilet studencki −51% (zł) | F6: FlixBus: czas | G6: FlixBus: cena od | H6: BlaBlaCar: cena (SZACUNEK) | I6: Paliwo za auto (zł) | J6: Paliwo na osobę przy 4 os. (zł) | K6: Źródła / uwagi
A7: Warszawa – Lublin | B7: 170 | C7: 1 h 52 min (IC, po modernizacji linii 7) | D7: 51 | E7: =D7*(1-$B$4) -> 24.99 | F7: ok. 1 h 55 – 2 h 35 | G7: 5,99 € | H7: szac. 25–35 zł + opłata serwisowa | I7: =B7*$B$2/100*$B$3 -> 75.0295 | J7: =I7/4 -> 18.757375 | K7: Pociąg: jawnylublin.pl / europodroze.pl (51–54 zł, 1:52–2:40). FlixBus: global.flixbus.com, omio. Dystans: szacunek (S17).
A8: Kraków – Rzeszów | B8: 165 | C8: 1 h 14 – 1 h 19 (EIP / IC Przemyślanin) | D8: 55 | E8: =D8*(1-$B$4) -> 26.95 | F8: ok. 2 h | G8: 9,48 USD | H8: szac. 25–35 zł + opłata serwisowa | I8: =B8*$B$2/100*$B$3 -> 72.82275 | J8: =I8/4 -> 18.205687 | K8: Pociąg: europodroze.pl (IC od 55 zł, EIP od 105 zł). FlixBus: flixbus.com. Dystans: szacunek (A4).
A9: Wrocław – Opole | B9: 95 | C9: 38 min (EC Danubius) | D9: 33 | E9: =D9*(1-$B$4) -> 16.17 | F9: ok. 1 h 15 | G9: 3,49 € | H9: szac. 15–20 zł + opłata | I9: =B9*$B$2/100*$B$3 -> 41.92825 | J9: =I9/4 -> 10.482062 | K9: Pociąg: europodroze.pl (EC/TLK/IC od 33 zł; regionalne taniej). FlixBus: flixbus.com. Dystans: szacunek (A4).
A11: BlaBlaCar – brak oficjalnych cenników tras; szacunek proporcjonalny do danych antyweb.pl dla Warszawa–Kraków (30–50 zł, średnio 40 zł). Agregator checkmybus podaje dla relacji Lublin–Warszawa i Kraków–Rzeszów ok. 13–19 USD.
A12: Wniosek: na trasach ~165–170 km student płaci za IC ok. 25–27 zł, a sam koszt paliwa na osobę (4 os.) to ok. 19 zł. Przestrzeń na opłatę platformy jest bardzo mała; na trasie Wrocław–Opole (38 min pociągiem) carpooling praktycznie nie ma przewagi.

Sheet Zrodla
A1: Źródło | B1: Link
A2: GUS: Szkolnictwo wyższe w roku akademickim 2025/2026 (15.06.2026) | B2: https://stat.gov.pl/obszary-tematyczne/edukacja/edukacja/szkolnictwo-wyzsze-w-roku-akademickim-20252026,8,12.html
A3: prawo.pl: Liczba studentów w roku akademickim 2025/26 – GUS | B3: https://www.prawo.pl/szkoly-i-uczelnie/liczba-studentow-w-polsce-w-roku-akademickim-2025-26-gus,1546639.html
A4: ISR: Studenci lgną do czterech województw (2025/26 wg województw) | B4: https://www.isr.info.pl/studenci-lgna-do-czterech-wojewodztw/
A5: bankier.pl: Ponad 1,28 mln studentów (GUS 2024/25, cudzoziemcy) | B5: https://www.bankier.pl/wiadomosc/Ponad-1-28-mln-studentow-w-Polsce-kobiety-wciaz-przewazaja-9032593.html
A6: Knight Frank: Prywatne akademiki w Polsce (studenci wg miast) | B6: https://content.knightfrank.com/research/2849/documents/pl/prywatne-akademiki-w-polsce-2025-12323.pdf
A7: US Lublin: Szkolnictwo wyższe w woj. lubelskim 2022/23 | B7: https://lublin.stat.gov.pl/opracowania-biezace/opracowania-sygnalne/edukacja/szkolnictwo-wyzsze-w-wojewodztwie-lubelskim-w-roku-akademickim-20222023,1,9.html
A8: PBS: EUROSTUDENT VIII | B8: https://pbs.pl/jak-sie-zyje-i-studiuje-w-polsce-eurostudent-viii/
A9: CBRE: W akademikach mieszka co dziesiąty student | B9: https://biuroprasowe.cbre.pl/97638-w-akademikach-mieszka-co-dziesiaty-student-powod-jest-prosty-tyle-jest-miejsc
A10: CBOS: Zachowania kierowców... (2018) | B10: https://www.cbos.pl/SPISKOM.POL/2018/K_113_18.PDF
A11: PKP Intercity: podróże koleją w 2025 roku | B11: https://www.intercity.pl/pl/site/o-nas/dzial-prasowy/aktualnosci/pkp-intercity:-podroze-koleja-w-2025-roku.html
A12: PKP Intercity: ulgi ustawowe | B12: https://www.intercity.pl/pl/site/dla-pasazera/kup-bilet/przepisy-i-taryfy/ulgi/ulgi-ustawowe/
... A45: cenauslug.pl: koszt stworzenia aplikacji mobilnej 2026 | B45: https://cenauslug.pl/poradniki/koszt-stworzenia-aplikacji-mobilnej-analiza-ux-design-i-dev
